Traceback (most recent call last):
  File "C:\Users\miaha\anaconda3\lib\site-packages\jupyter_cache\executors\utils.py", line 51, in single_nb_execution
    executenb(
  File "C:\Users\miaha\anaconda3\lib\site-packages\nbclient\client.py", line 1112, in execute
    return NotebookClient(nb=nb, resources=resources, km=km, **kwargs).execute()
  File "C:\Users\miaha\anaconda3\lib\site-packages\nbclient\util.py", line 74, in wrapped
    return just_run(coro(*args, **kwargs))
  File "C:\Users\miaha\anaconda3\lib\site-packages\nbclient\util.py", line 53, in just_run
    return loop.run_until_complete(coro)
  File "C:\Users\miaha\anaconda3\lib\asyncio\base_events.py", line 616, in run_until_complete
    return future.result()
  File "C:\Users\miaha\anaconda3\lib\site-packages\nbclient\client.py", line 553, in async_execute
    await self.async_execute_cell(
  File "C:\Users\miaha\anaconda3\lib\site-packages\nbclient\client.py", line 857, in async_execute_cell
    self._check_raise_for_error(cell, exec_reply)
  File "C:\Users\miaha\anaconda3\lib\site-packages\nbclient\client.py", line 760, in _check_raise_for_error
    raise CellExecutionError.from_cell_and_msg(cell, exec_reply_content)
nbclient.exceptions.CellExecutionError: An error occurred while executing the following cell:
------------------
# Basic libraries
import numpy as np
import pandas as pd
import json
import matplotlib.pyplot as plt
import seaborn as sns
import math
import time
import itertools

# Network libraries
import networkx as nx
from fa2 import ForceAtlas2 as FA2
import community

# NLP libraries
import re
import string
import nltk
from nltk.corpus import stopwords
from nltk import word_tokenize
from nltk.stem.porter import PorterStemmer
from nltk.probability import FreqDist
from wordcloud import WordCloud, ImageColorGenerator

# Display libraries
from IPython.display import display
from IPython.core.display import display as disp, HTML
from ipywidgets import widgets, interact, interactive, fixed, interact_manual
import imageio

from plotly import __version__
import plotly.io as pio
import plotly.express as px
import plotly.figure_factory as ff
import chart_studio.plotly as py
import plotly.offline
sns.set()

pio.renderers.default = 'notebook'
------------------

[1;31m---------------------------------------------------------------------------[0m
[1;31mModuleNotFoundError[0m                       Traceback (most recent call last)
[1;32m~\AppData\Local\Temp/ipykernel_18080/4260154088.py[0m in [0;36m<module>[1;34m[0m
[0;32m     34[0m [1;32mimport[0m [0mplotly[0m[1;33m.[0m[0mexpress[0m [1;32mas[0m [0mpx[0m[1;33m[0m[1;33m[0m[0m
[0;32m     35[0m [1;32mimport[0m [0mplotly[0m[1;33m.[0m[0mfigure_factory[0m [1;32mas[0m [0mff[0m[1;33m[0m[1;33m[0m[0m
[1;32m---> 36[1;33m [1;32mimport[0m [0mchart_studio[0m[1;33m.[0m[0mplotly[0m [1;32mas[0m [0mpy[0m[1;33m[0m[1;33m[0m[0m
[0m[0;32m     37[0m [1;32mimport[0m [0mplotly[0m[1;33m.[0m[0moffline[0m[1;33m[0m[1;33m[0m[0m
[0;32m     38[0m [0msns[0m[1;33m.[0m[0mset[0m[1;33m([0m[1;33m)[0m[1;33m[0m[1;33m[0m[0m

[1;31mModuleNotFoundError[0m: No module named 'chart_studio'
ModuleNotFoundError: No module named 'chart_studio'

