Traceback (most recent call last):
  File "C:\Users\miaha\anaconda3\lib\site-packages\jupyter_cache\executors\utils.py", line 51, in single_nb_execution
    executenb(
  File "C:\Users\miaha\anaconda3\lib\site-packages\nbclient\client.py", line 1112, in execute
    return NotebookClient(nb=nb, resources=resources, km=km, **kwargs).execute()
  File "C:\Users\miaha\anaconda3\lib\site-packages\nbclient\util.py", line 74, in wrapped
    return just_run(coro(*args, **kwargs))
  File "C:\Users\miaha\anaconda3\lib\site-packages\nbclient\util.py", line 53, in just_run
    return loop.run_until_complete(coro)
  File "C:\Users\miaha\anaconda3\lib\asyncio\base_events.py", line 616, in run_until_complete
    return future.result()
  File "C:\Users\miaha\anaconda3\lib\site-packages\nbclient\client.py", line 553, in async_execute
    await self.async_execute_cell(
  File "C:\Users\miaha\anaconda3\lib\site-packages\nbclient\client.py", line 857, in async_execute_cell
    self._check_raise_for_error(cell, exec_reply)
  File "C:\Users\miaha\anaconda3\lib\site-packages\nbclient\client.py", line 760, in _check_raise_for_error
    raise CellExecutionError.from_cell_and_msg(cell, exec_reply_content)
nbclient.exceptions.CellExecutionError: An error occurred while executing the following cell:
------------------
sns.set()
plt.figure(figsize = [18, 18])
plt.suptitle("Plot over in- and out-degree distribution for the SW GCC", fontsize=16)

#Plot in-degree
subax1 = plt.subplot(221)
plt.plot(deg_in, cnt_in, '.')
plt.xlabel('Degree')
plt.ylabel('Count')
plt.title('plot for in-degree distribution')
subax2 = plt.subplot(222)
plt.loglog(deg_in, cnt_in, '.')
plt.xlabel('Degree')
plt.ylabel('Count')
plt.title('Loglog plot for in-degree distribution')

#Plot out-degree
subax1 = plt.subplot(223)
plt.plot(deg_out, cnt_out, '.r')
plt.xlabel('Degree')
plt.ylabel('Count')
plt.title('plot for out-degree distribution')
subax2 = plt.subplot(224)
plt.loglog(deg_out, cnt_out, '.r')
plt.xlabel('Degree')
plt.ylabel('Count')
plt.title('Loglog plot for out-degree distribution')

plt.show()

------------------

[1;31m---------------------------------------------------------------------------[0m
[1;31mNameError[0m                                 Traceback (most recent call last)
[1;32m~\AppData\Local\Temp/ipykernel_15532/2994354797.py[0m in [0;36m<module>[1;34m[0m
[1;32m----> 1[1;33m [0msns[0m[1;33m.[0m[0mset[0m[1;33m([0m[1;33m)[0m[1;33m[0m[1;33m[0m[0m
[0m[0;32m      2[0m [0mplt[0m[1;33m.[0m[0mfigure[0m[1;33m([0m[0mfigsize[0m [1;33m=[0m [1;33m[[0m[1;36m18[0m[1;33m,[0m [1;36m18[0m[1;33m][0m[1;33m)[0m[1;33m[0m[1;33m[0m[0m
[0;32m      3[0m [0mplt[0m[1;33m.[0m[0msuptitle[0m[1;33m([0m[1;34m"Plot over in- and out-degree distribution for the SW GCC"[0m[1;33m,[0m [0mfontsize[0m[1;33m=[0m[1;36m16[0m[1;33m)[0m[1;33m[0m[1;33m[0m[0m
[0;32m      4[0m [1;33m[0m[0m
[0;32m      5[0m [1;31m#Plot in-degree[0m[1;33m[0m[1;33m[0m[1;33m[0m[0m

[1;31mNameError[0m: name 'sns' is not defined
NameError: name 'sns' is not defined

